<?xml version="1.0" encoding="UTF-8"?>
<!-- Generated by org.testng.reporters.JUnitReportReporter -->
<testsuite skipped="0" hostname="Admin-PC" name="scripts.TestSuite" tests="6" failures="1" timestamp="17 Oct 2017 04:40:21 GMT" time="251.928" errors="1">
  <testcase name="FacebookSignUpPage" time="37.561" classname="scripts.TestSuite"/>
  <testcase name="CalenderHandling" time="118.461" classname="scripts.TestSuite"/>
  <testcase name="loginToFB" time="22.392" classname="scripts.TestSuite">
    <error type="org.testng.TestNGException" message="
Some DataProvider public java.lang.String[][] scripts.TestSuite.dp(java.lang.String,java.lang.String) throws java.lang.Exception parameters unresolved:  at 0 type class java.lang.String
 at 1 type class java.lang.String
">
      <![CDATA[org.testng.TestNGException: 
Some DataProvider public java.lang.String[][] scripts.TestSuite.dp(java.lang.String,java.lang.String) throws java.lang.Exception parameters unresolved:  at 0 type class java.lang.String
 at 1 type class java.lang.String

	at org.testng.internal.MethodInvocationHelper.getParameters(MethodInvocationHelper.java:178)
	at org.testng.internal.MethodInvocationHelper.invokeDataProvider(MethodInvocationHelper.java:114)
	at org.testng.internal.Parameters.handleParameters(Parameters.java:612)
	at org.testng.internal.Invoker.handleParameters(Invoker.java:1316)
	at org.testng.internal.Invoker.createParameters(Invoker.java:1044)
	at org.testng.internal.Invoker.invokeTestMethods(Invoker.java:1134)
	at org.testng.internal.TestMethodWorker.invokeTestMethods(TestMethodWorker.java:125)
	at org.testng.internal.TestMethodWorker.run(TestMethodWorker.java:109)
	at org.testng.TestRunner.privateRun(TestRunner.java:776)
	at org.testng.TestRunner.run(TestRunner.java:634)
	at org.testng.SuiteRunner.runTest(SuiteRunner.java:425)
	at org.testng.SuiteRunner.runSequentially(SuiteRunner.java:420)
	at org.testng.SuiteRunner.privateRun(SuiteRunner.java:385)
	at org.testng.SuiteRunner.run(SuiteRunner.java:334)
	at org.testng.SuiteRunnerWorker.runSuite(SuiteRunnerWorker.java:52)
	at org.testng.SuiteRunnerWorker.run(SuiteRunnerWorker.java:86)
	at org.testng.TestNG.runSuitesSequentially(TestNG.java:1318)
	at org.testng.TestNG.runSuitesLocally(TestNG.java:1243)
	at org.testng.TestNG.runSuites(TestNG.java:1161)
	at org.testng.TestNG.run(TestNG.java:1129)
	at org.testng.remote.AbstractRemoteTestNG.run(AbstractRemoteTestNG.java:114)
	at org.testng.remote.RemoteTestNG.initAndRun(RemoteTestNG.java:251)
	at org.testng.remote.RemoteTestNG.main(RemoteTestNG.java:77)
]]>
    </error>
  </testcase> <!-- loginToFB -->
  <testcase name="checkValidUser" time="32.881" classname="scripts.TestSuite">
    <failure type="java.lang.AssertionError" message="expected [true] but found [false]">
      <![CDATA[java.lang.AssertionError: expected [true] but found [false]
	at org.testng.Assert.fail(Assert.java:93)
	at org.testng.Assert.failNotEquals(Assert.java:512)
	at org.testng.Assert.assertTrue(Assert.java:41)
	at org.testng.Assert.assertTrue(Assert.java:51)
	at scripts.TestSuite.checkValidUser(TestSuite.java:61)
	at sun.reflect.NativeMethodAccessorImpl.invoke0(Native Method)
	at sun.reflect.NativeMethodAccessorImpl.invoke(Unknown Source)
	at sun.reflect.DelegatingMethodAccessorImpl.invoke(Unknown Source)
	at java.lang.reflect.Method.invoke(Unknown Source)
	at org.testng.internal.MethodInvocationHelper.invokeMethod(MethodInvocationHelper.java:108)
	at org.testng.internal.Invoker.invokeMethod(Invoker.java:669)
	at org.testng.internal.Invoker.invokeTestMethod(Invoker.java:877)
	at org.testng.internal.Invoker.invokeTestMethods(Invoker.java:1201)
	at org.testng.internal.TestMethodWorker.invokeTestMethods(TestMethodWorker.java:125)
	at org.testng.internal.TestMethodWorker.run(TestMethodWorker.java:109)
	at org.testng.TestRunner.privateRun(TestRunner.java:776)
	at org.testng.TestRunner.run(TestRunner.java:634)
	at org.testng.SuiteRunner.runTest(SuiteRunner.java:425)
	at org.testng.SuiteRunner.runSequentially(SuiteRunner.java:420)
	at org.testng.SuiteRunner.privateRun(SuiteRunner.java:385)
	at org.testng.SuiteRunner.run(SuiteRunner.java:334)
	at org.testng.SuiteRunnerWorker.runSuite(SuiteRunnerWorker.java:52)
	at org.testng.SuiteRunnerWorker.run(SuiteRunnerWorker.java:86)
	at org.testng.TestNG.runSuitesSequentially(TestNG.java:1318)
	at org.testng.TestNG.runSuitesLocally(TestNG.java:1243)
	at org.testng.TestNG.runSuites(TestNG.java:1161)
	at org.testng.TestNG.run(TestNG.java:1129)
	at org.testng.remote.AbstractRemoteTestNG.run(AbstractRemoteTestNG.java:114)
	at org.testng.remote.RemoteTestNG.initAndRun(RemoteTestNG.java:251)
	at org.testng.remote.RemoteTestNG.main(RemoteTestNG.java:77)
]]>
    </failure>
  </testcase> <!-- checkValidUser -->
  <testcase name="testPopUp" time="28.835" classname="scripts.TestSuite"/>
  <testcase name="Bootstrap_dropdown" time="11.798" classname="scripts.TestSuite"/>
</testsuite> <!-- scripts.TestSuite -->
